[pytest] assert_called_once

---
description: assert_called_once is valid since python3.6 (could fails silently in 3.5?)
---

# assert\_called\_once

```
Traceback (most recent call last):
  File "/Users/tobiaszkedzierski/.pyenv/versions/3.5.7/lib/python3.5/unittest/mock.py", line 1159, in patched
    return func(*args, **keywargs)
  File "/Users/tobiaszkedzierski/PycharmProjects/AIRFLOW/airflow-breeze-gcp-extension/workspaces/polidea-main/airflow/test_assert_called_once.py", line 18, in test_encrypt
    x = mock.assert_called_once()
  File "/Users/tobiaszkedzierski/.pyenv/versions/3.5.7/lib/python3.5/unittest/mock.py", line 585, in __getattr__
    raise AttributeError(name)
AttributeError: assert_called_once
```

> `assert_called_once()` ~~silently returns a mock object (3.5)~~ Article says wrong??

http://engineroom.trackmaven.com/blog/mocking-mistakes/



id: ab68297d900f40a3a08dda7556abaf16
parent_id: 8150aa29934e4b5f948a36b6a29a3459
created_time: 2022-06-17T11:59:14.809Z
updated_time: 2022-06-17T12:04:59.156Z
is_conflict: 0
latitude: 0.00000000
longitude: 0.00000000
altitude: 0.0000
author: 
source_url: 
is_todo: 0
todo_due: 0
todo_completed: 0
source: joplin-desktop
source_application: net.cozic.joplin-desktop
application_data: 
order: 1655467182363
user_created_time: 2022-06-17T11:59:14.809Z
user_updated_time: 2022-06-17T12:04:59.156Z
encryption_cipher_text: 
encryption_applied: 0
markup_language: 1
is_shared: 0
share_id: 
conflict_original_id: 
master_key_id: 
type_: 1